Workbook

Sheet Assumptions |

Sheet Summary
A1: DIAMONDBACK ENERGY (FANG) — FORECAST ASSUMPTIONS | 2026E–2030E | Bear / Base / Bull Scenarios
A2: Category | B2: Assumption | C2: Unit | D2: Historicals | G2: BEAR | L2: BASE | Q2: BULL | V2: Historical Trend | W2: Management Guidance | X2: Rationale & Basis
D3: 2023A | E3: 2024A | F3: 2025A | G3: 2026 | H3: 2027 | I3: 2028 | J3: 2029 | K3: 2030 | L3: 2026 | M3: 2027 | N3: 2028 | O3: 2029 | P3: 2030 | Q3: 2026 | R3: 2027 | S3: 2028 | T3: 2029 | U3: 2030
A4: A. PRODUCTION
A5: Production | B5: Oil production growth (YoY %) | C5: % | D5: ='Operating Metrics'!D3/'Operating Metrics'!G3-1 -> 0.17839639 | E5: ='Operating Metrics'!E3/'Operating Metrics'!D3-1 -> 0.28228456 | F5: ='Operating Metrics'!F3/'Operating Metrics'!E3-1 -> 0.47141293 | G5: 0.045 | H5: =G5-1% -> 0.035 | I5: =H5-1% -> 0.025 | J5: =I5-0.5% -> 0.02 | K5: =J5-0.5% -> 0.015 | L5: 0.05 | M5: =L5-1% -> 0.04 | N5: =M5-1% -> 0.03 | O5: =N5-0.5% -> 0.025 | P5: =O5-0.5% -> 0.02 | Q5: 0.055 | R5: =Q5-1% -> 0.045 | S5: =R5-1% -> 0.035 | T5: =S5-0.5% -> 0.03 | U5: =T5-0.5% -> 0.025 | V5: 2024: +28% / 2025: +47% — both acquisition-driven (Endeavor closed Sept 2024). | W5: 2026 Q1: Increasing annual oil production guidance to 520+ (from 500 - 510) MBO/d and total BOE production to 972+ (from 926 - 962) MBOE/d; implying ~5% organic year-over-year growth | X5: Post-acquisition, FANG's Tier 1 Midland Basin inventory supports low-single-digit organic growth. Growth is progressively normalized toward 2% by 2030 to reflect inventory depletion. No M&A assumed.
A6: Production | B6: Gas production growth (YoY %) | C6: % | D6: ='Operating Metrics'!D4/'Operating Metrics'!G4-1 -> 0.12326507 | E6: ='Operating Metrics'!E4/'Operating Metrics'!D4-1 -> 0.39150098 | F6: ='Operating Metrics'!F4/'Operating Metrics'!E4-1 -> 0.62454658 | G6: =G5+1% -> 0.055 | H6: =G6-1% -> 0.045 | I6: =H6-1% -> 0.035 | J6: =I6-0.5% -> 0.03 | K6: =J6-0.5% -> 0.025 | L6: =L5+1% -> 0.06 | M6: =L6-1% -> 0.05 | N6: =M6-1% -> 0.04 | O6: =N6-0.5% -> 0.035 | P6: =O6-0.5% -> 0.03 | Q6: =Q5+1% -> 0.065 | R6: =Q6-1% -> 0.055 | S6: =R6-1% -> 0.045 | T6: =S6-0.5% -> 0.04 | U6: =T6-0.5% -> 0.035 | V6: also acquisition-driven | W6: No explicit gas production guidance; grows with oil wells. | X6: The company's gas oil ratio has increased from 2.06 to 2.24 to 2.47 in the past 3 years, gas is growing slightly faster than oil, reflecting larger post-Endeavor asset base and somewhat gassier production mix
A7: Production | B7: NGL production growth (YoY %) | C7: % | D7: ='Operating Metrics'!D5/'Operating Metrics'!G5-1 -> 0.14514726 | E7: ='Operating Metrics'!E5/'Operating Metrics'!D5-1 -> 0.45249437 | F7: ='Operating Metrics'!F5/'Operating Metrics'!E5-1 -> 0.61112676 | G7: 0.025 | H7: 0.02 | I7: 0.02 | J7: 0.015 | K7: 0.015 | L7: 0.04 | M7: 0.035 | N7: 0.03 | O7: 0.025 | P7: 0.025 | Q7: 0.045 | R7: 0.04 | S7: 0.035 | T7: 0.03 | U7: 0.025 | V7: also acquisition-driven | W7: No explicit NGL guidance; tracks oil and gas processing activity. | X7: NGL growth tracks oil activity and gas processing utilization. forecast NGL mix is assumed to stabilize near current levels rather than continue increasing at the historical rate.
A8: B. COMMODITY PRICING
A9: Pricing | B9: WTI oil price assumption ($/Bbl) | C9: $/Bbl | D9: 77.77 | E9: 75.53 | F9: 64.2 | G9: 71.83 | H9: 68.73 | I9: 65 | J9: 65 | K9: 65.46 | L9: 82.71 | M9: 73.08 | N9: 70.77 | O9: 70.82 | P9: 71.05 | Q9: 89 | R9: 78.1 | S9: 78.3 | T9: 75 | U9: 75 | V9: Jan 2026: $65, Feb: $67, Mar: $101, Apr: $105, May: $87, Jun: $80. Volatility driven by Iran/Strait of Hormuz geopolitical events.(Investing.com) | W9: FANG does not publicly guide WTI. | X9: The base case is estimated using future strips (S&P Capital IQ WTI Crude Oil Future Contracts; Using annual average). Given exceptional geopolitical uncertainty in global oil markets, valuation is presented under three commodity-price scenarios rather than a single deterministic forecast.
A10: Pricing | B10: FANG realized oil price ($/Bbl) | C10: $/Bbl | D10: ='Operating Metrics'!D7 -> 75.68 | E10: ='Operating Metrics'!E7 -> 73.52 | F10: ='Operating Metrics'!F7 -> 64.04 | G10: =G9-1.5 -> 70.33 | H10: =H9-1.5 -> 67.23 | I10: =I9-1.5 -> 63.5 | J10: =J9-1.5 -> 63.5 | K10: =K9-1.5 -> 63.96 | L10: =L9-1.5 -> 81.21 | M10: =M9-1.5 -> 71.58 | N10: =N9-1.5 -> 69.27 | ... U10: =U9-1.5 -> 73.5 | V10: Realized discount to WTI: 2023 -$2.09, 2024 -$2.01, 2025 -$0.16. The average WTI differential is around -$1.5 | W10: FANG does not publicly guide WTI. | X10: Oil-price assumptions are based on Capital IQ analyst consensus estimates. Realized oil prices are derived by applying Diamondback's historical discount to WTI of approximately $1.5/bbl.
A11: Pricing | B11: Realized natural gas price ($/MMBtu) | C11: $/MMBtu | D11: ='Operating Metrics'!D8 -> 1.32 | E11: ='Operating Metrics'!E8 -> 0.32 | F11: ='Operating Metrics'!F8 -> 0.89 | G11: =3.24-1.9 -> 1.34 | H11: =3.35-1.9 -> 1.45 | I11: =3.35-1.9 -> 1.45 | J11: =3.55-1.9 -> 1.65 | K11: =3.55-1.9 -> 1.65 | L11: =3.73-1.9 -> 1.83 | M11: =3.78-1.9 -> 1.88 | N11: =3.84-1.9 -> 1.94 | O11: =3.95-1.9 -> 2.05 | P11: =3.96-1.9 -> 2.06 | Q11: =5-1.9 -> 3.1 | R11: =5-1.9 -> 3.1 | S11: =5-1.9 -> 3.1 | T11: =5-1.9 -> 3.1 | U11: =5-1.9 -> 3.1 | V11: Natural Gas - Henry Hub: 2023 $2.53, 2024 $2.19, 2025 $3.52.Realized discount for each year: 2023 -$1.21, 2024 -$1.87, 2025 -$2.63. Differential is around -$1.9 | W11: No explicit gas price guidance. | X11: Natural gas price assumptions are based on Capital IQ analyst consensus estimates.
A12: Pricing | B12: Realized NGL price ($/Bbl) | C12: $/Bbl | D12: ='Operating Metrics'!D9 -> 20.08 | E12: ='Operating Metrics'!E9 -> 18.99 | F12: ='Operating Metrics'!F9 -> 17.88 | G12: =26%*G9 -> 18.6758 | H12: =26%*H9 -> 17.8698 | I12: =26%*I9 -> 16.9 | J12: =26%*J9 -> 16.9 | K12: =26%*K9 -> 17.0196 | L12: =26%*L9 -> 21.5046 | M12: =26%*M9 -> 19.0008 | N12: =26%*N9 -> 18.4002 | ... U12: =26%*U9 -> 19.5 | V12: Mont Belvieu TX Propane spot price: 2023 $29.86, 2024 $32.67, 2025 $ 31.5 (EIA). FANG's NGL realization is usually 60% of Mont Belvieu and 26% of WTI | W12: No explicit guidance. NGL tracks WTI and Mont Belvieu propane / ethane prices. | X12: Assume the realization rate to WTI remains stably at 26%.
A13: C. UNIT OPERATING COSTS ($/BOE)
A14: Unit Costs | B14: Lease operating expenses (LOE) per BOE | C14: $/BOE | D14: ='Operating Metrics'!D11 -> 5.34 | E14: ='Operating Metrics'!E11 -> 5.87 | F14: ='Operating Metrics'!F11 -> 5.55 | G14: 5.5 | H14: =G14-0.05 -> 5.45 | I14: =H14-0.05 -> 5.4 | J14: =I14-0.05 -> 5.35 | K14: =J14-0.05 -> 5.3 | L14: 5.5 | M14: =L14-0.05 -> 5.45 | N14: =M14-0.05 -> 5.4 | O14: =N14-0.05 -> 5.35 | P14: =O14-0.05 -> 5.3 | Q14: 5.5 | R14: =Q14-0.05 -> 5.45 | S14: =R14-0.05 -> 5.4 | T14: =S14-0.05 -> 5.35 | U14: =T14-0.05 -> 5.3 | V14: 2024: $5.87 (integration cost spike on Endeavor) → 2025: $5.55 (normalising). FANG is consistently a top-quartile low-cost Permian operator. | W14: 2025 Q3 guidance ~$5.40–5.70/BOE. FANG targets sub-$6/BOE LOE structurally. | X14: Using 2025 as the normalized benchmark: BOE growth and scale efficiencies support gradual LOE improvement. Oilfield service inflation and labor cost increases offset part of the benefit. Assume LOE declines by 0.05 per year
A15: Unit Costs | B15: Production & ad valorem taxes per BOE | C15: $/BOE | D15: ='Operating Metrics'!D12 -> 3.21 | E15: ='Operating Metrics'!E12 -> 2.91 | F15: ='Operating Metrics'!F12 -> 2.53 | G15: =3.97%*G9 -> 2.851651 | H15: =3.97%*H9 -> 2.728581 | I15: =3.97%*I9 -> 2.5805 | J15: =3.97%*J9 -> 2.5805 | K15: =3.97%*K9 -> 2.598762 | L15: =3.97%*L9 -> 3.283587 | M15: =3.97%*M9 -> 2.901276 | N15: =3.97%*N9 -> 2.809569 | ... U15: =3.97%*U9 -> 2.9775 | V15: Declining trend reflects commodity-price-linked structure plus mix shift toward lower-tax Permian Basin acreage. | W15: Commodity-price-linked; not explicitly guided per BOE. | X15: The Tax/BOE over WTI ratios remained at ~3.97% throughout the past 3 years.
A16: Unit Costs | B16: Gathering, processing & transport (GPT) per BOE | C16: $/BOE | D16: ='Operating Metrics'!D13 -> 1.76 | E16: ='Operating Metrics'!E13 -> 1.63 | F16: ='Operating Metrics'!F13 -> 1.53 | G16: 1.52 | H16: =G16-0.02 -> 1.5 | I16: =H16-0.02 -> 1.48 | J16: =I16-0.02 -> 1.46 | K16: =J16-0.02 -> 1.44 | L16: 1.52 | M16: =L16-0.02 -> 1.5 | N16: =M16-0.02 -> 1.48 | O16: =N16-0.02 -> 1.46 | P16: =O16-0.02 -> 1.44 | Q16: 1.52 | R16: =Q16-0.02 -> 1.5 | S16: =R16-0.02 -> 1.48 | T16: =S16-0.02 -> 1.46 | U16: =T16-0.02 -> 1.44 | V16: Consistent improvement driven by Rattler/midstream contract scale benefits and Endeavor's lower-cost gathering agreements in Midland Basin. From 2023 to 2025, GPT/BOE already decreased by 13%. | W16: 2025 Q3 guidance ~1.45–1.60/BOE. FANG has guided structurally lower GPT as Endeavor volumes leverage existing midstream infrastructure. | X16: GPT per BOE is forecast to decline modestly as higher production volumes are transported through largely fixed midstream infrastructure, allowing unit transportation costs to benefit from economies of scale and volume-based contract discounts.
A17: Unit Costs | B17: General & administrative expenses (G&A) per BOE | C17: $/BOE | D17: ='Operating Metrics'!D14 -> 0.59 | E17: ='Operating Metrics'!E14 -> 0.68 | F17: ='Operating Metrics'!F14 -> 0.62 | G17: 0.6 | H17: =G17-0.02 -> 0.58 | I17: =H17-0.02 -> 0.56 | J17: =I17-0.02 -> 0.54 | K17: =J17-0.02 -> 0.52 | L17: 0.6 | M17: =L17-0.02 -> 0.58 | N17: =M17-0.02 -> 0.56 | O17: =N17-0.02 -> 0.54 | P17: =O17-0.02 -> 0.52 | Q17: 0.6 | R17: =Q17-0.02 -> 0.58 | S17: =R17-0.02 -> 0.56 | T17: =S17-0.02 -> 0.54 | U17: =T17-0.02 -> 0.52 | V17: 2024: $0.68 (integration & transaction costs) → 2025: $0.62 (normalising). FANG has best-in-class G&A structure for a large-cap E&P. | W17: 2025 Q3 guidance cash G&A $0.60-0.75/BOE, Non-cash G&A $ 0.25-0.35/BOE | X17: G&A per BOE is expected to decline gradually as corporate overhead grows more slowly than production volumes. The forecast assumes a largely fixed administrative cost base that is increasingly diluted across a larger production platform.
A18: D. DEPRECIATION, DEPLETION & AMORTIZATION
A19: DD&A | B19: DD&A per BOE ($/BOE) | C19: $/BOE | D19: ='Cash Flow Statement'!E7/'Operating Metrics'!D6*1000000/1000 -> 10.684584 | E19: ='Cash Flow Statement'!F7/'Operating Metrics'!E6*1000000/1000 -> 13.015363 | F19: ='Cash Flow Statement'!G7/'Operating Metrics'!F6*1000000/1000 -> 14.986109 | G19: 15 | H19: 15 | I19: 15 | J19: 15 | K19: 15 | L19: 15 | M19: 15 | N19: 15 | O19: 15 | P19: 15 | Q19: 15 | R19: 15 | S19: 15 | T19: 15 | U19: 15 | V19: Sharp increase driven by high cost basis of Endeavor acquisition assets ($39B gross PP&E added). 2025 DD&A of $5,038M includes elevated amortization of acquired proved reserves. | W19: No explicit DD&A/BOE guidance. | X19: DD&A per BOE is held constant at approximately $15/BOE throughout the forecast period. . As no major acquisitions are assumed in the forecast period, DD&A is expected to remain broadly stable rather than continue increasing.
A20: E. CAPITAL EXPENDITURE
A21: Capex | B21: Total D&C capex ($M) | C21: $M | D21: =-'Operating Metrics'!D15 -> 2701 | E21: =-'Operating Metrics'!E15 -> 2867 | F21: =-'Operating Metrics'!F15 -> 3523 | G21: 3900 | H21: =G21*1.03 -> 4017 | I21: =H21*1.02 -> 4097.34 | J21: =I21*1.02 -> 4179.2868 | K21: =J21*1.02 -> 4262.8725 | L21: 3900 | M21: =L21*1.03 -> 4017 | N21: =M21*1.02 -> 4097.34 | O21: =N21*1.02 -> 4179.2868 | P21: =O21*1.02 -> 4262.8725 | Q21: 3900 | R21: =Q21*1.03 -> 4017 | S21: =R21*1.02 -> 4097.34 | T21: =S21*1.02 -> 4179.2868 | U21: =T21*1.02 -> 4262.8725 | V21: Capital efficiency improving sharply as production base doubles. Excludes property acquisitions ($2B+ in 2023, $8.9B in 2024). | W21: 2026 Q1 guidance for capex is 3.90Bn. | X21: Capex is held constant across scenarios and is based on management's 2026 guidance of approximately $3.9 billion. Future capex is assumed to increase modestly by 2–3% per annum, reflecting reserve replacement requirements and inflationary pressures.
A22: F. VALUATION PARAMETERS
A23: Valuation | B23: Effective corporate tax rate (%) | C23: % | D23: ='Income Statement'!E42/'Income Statement'!E40 -> 0.21468927 | E23: ='Income Statement'!F42/'Income Statement'!F40 -> 0.17773828 | F23: ='Income Statement'!G42/'Income Statement'!G40 -> 0.17449306 | G23: 0.2 | H23: 0.2 | I23: 0.2 | J23: 0.2 | K23: 0.2 | L23: 0.2 | M23: 0.2 | N23: 0.2 | O23: 0.2 | P23: 0.2 | Q23: 0.2 | R23: 0.2 | S23: 0.2 | T23: 0.2 | U23: 0.2 | V23: 2023: 21.5% (near-statutory). 2024: 17.8% (higher IDC deductions on Endeavor acquisition D&C). 2025: 17.4% — depressed by $3.65B impairment reducing taxable income (normalized 2025 tax rate ~21%). | W23: No formal tax rate guidance. | X23: Normalized rate 20% reflects: 21% federal statutory rate, less IDC benefit (~1–2pp)
A24: Valuation | B24: WACC | C24: % | G24: 0.065 | H24: 0.065 | I24: 0.065 | J24: 0.065 | K24: 0.065 | L24: 0.065 | M24: 0.065 | N24: 0.065 | O24: 0.065 | P24: 0.065 | Q24: 0.065 | R24: 0.065 | S24: 0.065 | T24: 0.065 | U24: 0.065 | W24: No formal guidance | X24: detailed in WACC spreadsheet
A25: Valuation | B25: Terminal Growth Rate | C25: % | G25: ='Terminal Growth'!$I$26 -> 0.01 | H25: ='Terminal Growth'!$I$26 -> 0.01 | I25: ='Terminal Growth'!$I$26 -> 0.01 | J25: ='Terminal Growth'!$I$26 -> 0.01 | K25: ='Terminal Growth'!$I$26 -> 0.01 | L25: ='Terminal Growth'!$I$26 -> 0.01 | M25: ='Terminal Growth'!$I$26 -> 0.01 | N25: ='Terminal Growth'!$I$26 -> 0.01 | ... U25: ='Terminal Growth'!$I$26 -> 0.01 | V25: Based on RRR calculation in Terminal Growth spreadsheet | W25: No formal guidance | X25: Organic reserve replacement averaged below 100% in 2024–2025, suggesting that reserve additions did not fully offset annual production. However, these years coincided with the integration of the Endeavor acquisition and may not fully reflect Diamondback's long-run reserve replacement capability. Historical reserve replacement exceeded 100% prior to the acquisition, while management continues to guide for organic production growth. As a result, a conservative terminal growth rate of 1.5% is adopted in the base case, representing modest long-term growth that is below nominal GDP growth but above a zero-growth run-off scenario.

Sheet WACC
B2: This is based on 2025 year end data
B3: WACC=D/A*(1-T)*Rd+E/A*Re | D3: =D6*D8+D7*D11 -> 0.065023654
C4: Debt | D4: ='Balance Sheet'!G24+'Balance Sheet'!G30 -> 14489 | E4: Million | F4: =_xlfn.FORMULATEXT(D4) -> ='Balance Sheet'!G24+'Balance Sheet'!G30
C5: Equity | D5: =289.079*150.33 -> 43457.246 | E5: Million | F5: common stock:0.289079B, share price (close): $150.33 on 12/31/2025
C6: D/A | D6: =D4/(D4+D5) -> 0.25004208
C7: E/A | D7: =D5/(D4+D5) -> 0.74995792
C8: Cost of Debt (post tax) | D8: =D9*(1-D10) -> 0.04104
C9: Cost of Debt (pre tax) | D9: 0.0513 | F9: Estimated using the weighted average coupon rate of outstanding debt securities. This is used as a proxy for the market cost of debt, as Diamondback maintains an investment-grade credit profile and coupon rates are broadly representative of current borrowing costs.
C10: tax rate | D10: =Summary!L23 -> 0.2 | F10: same as Assumptions
C11: Cost of Equity | D11: =D12+D13*D14 -> 0.07302
C12: Risk Free Rate | D12: 0.0418 | F12: 46022
C13: Levered Beta | D13: 0.7 | F13: 3Y beta from Capital IQ
C14: Equity Risk Premium | D14: 0.0446 | F14: based on US country ERM published by Damodaran (2026)
B16: WACC=D/A*(1-T)*Rd+E/A*Re | D16: =D19*D21+D20*D24 -> 0.067988742
C17: Debt | D17: =DCF!J26+DCF!J27 -> 13898 | E17: Million | F17: = current portion of long term debt + long term debt
C18: Equity | D18: =DCF!J29*DCF!J30 -> 55640.957 | E18: Million | F18: = common stock * Share price
C19: D/A | D19: =D17/(D17+D18) -> 0.1998592
C20: E/A | D20: =D18/(D17+D18) -> 0.8001408
C21: Cost of Debt (post tax) | D21: =D22*(1-D23) -> 0.04104
C22: Cost of Debt (pre tax) | D22: 0.0513 | F22: Estimated using the weighted average coupon rate of outstanding debt securities. This is used as a proxy for the market cost of debt, as Diamondback maintains an investment-grade credit profile and coupon rates are broadly representative of current borrowing costs.
C23: tax rate | D23: =20% -> 0.2 | F23: same as Assumptions
C24: Cost of Equity | D24: =D25+D26*D27 -> 0.07472
C25: Risk Free Rate | D25: 0.0435 | F25: 46111
C26: Levered Beta | D26: 0.7 | F26: 3Y beta from Capital IQ
C27: Equity Risk Premium | D27: 0.0446 | F27: based on US country ERM published by Damodaran (2026)
B28: This is based on 2026 Q1 data

Sheet Terminal Growth
A1: Raw Data
A2: S&P Capital IQ - Standard | B2: 2021 FY | C2: 2022 FY | D2: 2023 FY | E2: 2024 FY | F2: 2025 FY | H2: RRR Calculation | I2: 2021 FY | J2: 2022 FY | K2: 2023 FY | L2: 2024 FY | M2: 2025 FY
A3: Oil Reserves (in MMbbls) | H3: Oil Reserves (in MMboe)
A4: Production, Oil | B4: -81.522 | C4: -81.616 | D4: -96.176 | E4: -123.325 | F4: -181.462 | H4: Production, Oil | I4: =B4*1 -> -81.522 | J4: =C4*1 -> -81.616 | K4: =D4*1 -> -96.176 | L4: =E4*1 -> -123.325 | M4: =F4*1 -> -181.462
A5: Reserve Revisions, Oil | B5: -160.57 | C5: -10.483 | D5: -56.482 | E5: -78.142 | F5: -173.561 | H5: Reserve Revisions, Oil | I5: =B5*1 -> -160.57 | J5: =C5*1 -> -10.483 | K5: =D5*1 -> -56.482 | L5: =E5*1 -> -78.142 | M5: =F5*1 -> -173.561
A6: Reserve Additions, Oil | B6: 271.222 | C6: 201.326 | D6: 206.562 | E6: 168.375 | F6: 306.431 | H6: Reserve Additions, Oil | I6: =B6*1 -> 271.222 | J6: =C6*1 -> 201.326 | K6: =D6*1 -> 206.562 | L6: =E6*1 -> 168.375 | M6: =F6*1 -> 306.431
A7: Gas Reserves (in Bcf) | H7: Gas Reserves (in MMboe)
A8: Production, Gas | B8: -169.406 | C8: -176.376 | D8: -198.117 | E8: -275.68 | F8: -447.855 | H8: Production, Gas | I8: =B8/6 -> -28.234333 | J8: =C8/6 -> -29.396 | K8: =D8/6 -> -33.0195 | L8: =E8/6 -> -45.946667 | M8: =F8/6 -> -74.6425
A9: Reserve Revisions, Gas | B9: 195.302 | C9: 2.827 | D9: -47.697 | E9: -158.468 | F9: -253.282 | H9: Reserve Revisions, Gas | I9: =B9/6 -> 32.550333 | J9: =C9/6 -> 0.47116667 | K9: =D9/6 -> -7.9495 | L9: =E9/6 -> -26.411333 | M9: =F9/6 -> -42.213667
A10: Reserve Additions, Gas | B10: 720.125 | C10: 386.987 | D10: 424.881 | E10: 310.421 | F10: 765.623 | H10: Reserve Additions, Gas | I10: =B10/6 -> 120.02083 | J10: =C10/6 -> 64.497833 | K10: =D10/6 -> 70.8135 | L10: =E10/6 -> 51.736833 | M10: =F10/6 -> 127.60383
A11: NGL Reserves (in MMbbls) | H11: NGL Reserves (in MMboe)
A12: Production, NGL | B12: -27.246 | C12: -29.88 | D12: -34.217 | E12: -49.7 | F12: -80.073 | H12: Production, NGL | I12: =B12*1 -> -27.246 | J12: =C12*1 -> -29.88 | K12: =D12*1 -> -34.217 | L12: =E12*1 -> -49.7 | M12: =F12*1 -> -80.073
A13: Reserve Revisions, NGL | B13: -6.685 | C13: 3.228 | D13: 9.962 | E13: -24.518 | F13: -88.31 | H13: Reserve Revisions, NGL | I13: =B13*1 -> -6.685 | J13: =C13*1 -> 3.228 | K13: =D13*1 -> 9.962 | L13: =E13*1 -> -24.518 | M13: =F13*1 -> -88.31
A14: Reserve Additions, NGL | B14: 127.479 | C14: 68.671 | D14: 78.498 | E14: 58.696 | F14: 144.884 | H14: Reserve Additions, NGL | I14: =B14*1 -> 127.479 | J14: =C14*1 -> 68.671 | K14: =D14*1 -> 78.498 | L14: =E14*1 -> 58.696 | M14: =F14*1 -> 144.884
H15: Total
H16: Production | I16: =I4+I8+I12 -> -137.00233 | J16: =J4+J8+J12 -> -140.892 | K16: =K4+K8+K12 -> -163.4125 | L16: =L4+L8+L12 -> -218.97167 | M16: =M4+M8+M12 -> -336.1775
H17: Organic Addition, Oil | I17: =I5+I6 -> 110.652 | J17: =J5+J6 -> 190.843 | K17: =K5+K6 -> 150.08 | L17: =L5+L6 -> 90.233 | M17: =M5+M6 -> 132.87
H18: Organic Addition, Gas | I18: =I9+I10 -> 152.57117 | J18: =J9+J10 -> 64.969 | K18: =K9+K10 -> 62.864 | L18: =L9+L10 -> 25.3255 | M18: =M9+M10 -> 85.390167
H19: Organic Addition, NGL | I19: =I13+I14 -> 120.794 | J19: =J13+J14 -> 71.899 | K19: =K13+K14 -> 88.46 | L19: =L13+L14 -> 34.178 | M19: =M13+M14 -> 56.574
H20: RRR
H21: RRR, Oil | I21: =I17/-I4 -> 1.3573269 | J21: =J17/-J4 -> 2.3383038 | K21: =K17/-K4 -> 1.5604725 | L21: =L17/-L4 -> 0.73166836 | M21: =M17/-M4 -> 0.73221942
H22: RRR, Gas | I22: =I18/-I8 -> 5.403746 | J22: =J18/-J8 -> 2.2101306 | K22: =K18/-K8 -> 1.9038447 | L22: =L18/-L8 -> 0.55119341 | M22: =M18/-M8 -> 1.1439886
H23: RRR, NGL | I23: =I19/-I12 -> 4.4334581 | J23: =J19/-J12 -> 2.4062584 | K23: =K19/-K12 -> 2.5852646 | L23: =L19/-L12 -> 0.68768612 | M23: =M19/-M12 -> 0.70653029
H24: RRR, Combined | I24: =(I17+I18+I19)/-I16 -> 2.8029973 | J24: =(J17+J18+J19)/-J16 -> 2.3259731 | K24: =(K17+K18+K19)/-K16 -> 1.8444366 | L24: =(L17+L18+L19)/-L16 -> 0.68381678 | M24: =(M17+M18+M19)/-M16 -> 0.81752695
H26: Terminal Growth Rate | I26: 0.01

Sheet Forecast |

Sheet Forecast_IS
A1: DIAMONDBACK ENERGY (FANG) — FORECAST INCOME STATEMENT | $M | 2026E–2030E
B2: HISTORICAL | E2: BEAR | J2: BASE | O2: BULL
B3: 2023A | C3: 2024A | D3: 2025A | E3: 2026E | F3: 2027E | G3: 2028E | H3: 2029E | I3: 2030E | J3: 2026E | K3: 2027E | L3: 2028E | M3: 2029E | N3: 2030E | O3: 2026E | P3: 2027E | Q3: 2028E | R3: 2029E | S3: 2030E
A4: PRODUCTION VOLUMES
A5: Oil Production (MBbl) | B5: ='Operating Metrics'!D3 -> 96176 | C5: ='Operating Metrics'!E3 -> 123325 | D5: ='Operating Metrics'!F3 -> 181462 | E5: =D5*(1+Summary!G5) -> 189627.79 | F5: =E5*(1+Summary!H5) -> 196264.76 | G5: =F5*(1+Summary!I5) -> 201171.38 | H5: =G5*(1+Summary!J5) -> 205194.81 | I5: =H5*(1+Summary!K5) -> 208272.73 | J5: =D5*(1+Summary!L5) -> 190535.1 | K5: =J5*(1+Summary!M5) -> 198156.5 | L5: =K5*(1+Summary!N5) -> 204101.2 | M5: =L5*(1+Summary!O5) -> 209203.73 | N5: =M5*(1+Summary!P5) -> 213387.8 | O5: =D5*(1+Summary!Q5) -> 191442.41 | P5: =O5*(1+Summary!R5) -> 200057.32 | Q5: =P5*(1+Summary!S5) -> 207059.32 | R5: =Q5*(1+Summary!T5) -> 213271.1 | S5: =R5*(1+Summary!U5) -> 218602.88
A6: Natural Gas Production (MMcf) | B6: ='Operating Metrics'!D4 -> 198117 | C6: ='Operating Metrics'!E4 -> 275680 | D6: ='Operating Metrics'!F4 -> 447855 | E6: =D6*(1+Summary!G6) -> 472487.02 | F6: =E6*(1+Summary!H6) -> 493748.94 | G6: =F6*(1+Summary!I6) -> 511030.15 | H6: =G6*(1+Summary!J6) -> 526361.06 | I6: =H6*(1+Summary!K6) -> 539520.09 | J6: =D6*(1+Summary!L6) -> 474726.3 | K6: =J6*(1+Summary!M6) -> 498462.62 | L6: =K6*(1+Summary!N6) -> 518401.12 | M6: =L6*(1+Summary!O6) -> 536545.16 | N6: =M6*(1+Summary!P6) -> 552641.51 | O6: =D6*(1+Summary!Q6) -> 476965.57 | P6: =O6*(1+Summary!R6) -> 503198.68 | Q6: =P6*(1+Summary!S6) -> 525842.62 | R6: =Q6*(1+Summary!T6) -> 546876.33 | S6: =R6*(1+Summary!U6) -> 566017
A7: NGL Production (MBbl) | B7: ='Operating Metrics'!D5 -> 34217 | C7: ='Operating Metrics'!E5 -> 49700 | D7: ='Operating Metrics'!F5 -> 80073 | E7: =D7*(1+Summary!G7) -> 82074.825 | F7: =E7*(1+Summary!H7) -> 83716.322 | G7: =F7*(1+Summary!I7) -> 85390.648 | H7: =G7*(1+Summary!J7) -> 86671.508 | I7: =H7*(1+Summary!K7) -> 87971.58 | J7: =D7*(1+Summary!L7) -> 83275.92 | K7: =J7*(1+Summary!M7) -> 86190.577 | L7: =K7*(1+Summary!N7) -> 88776.295 | M7: =L7*(1+Summary!O7) -> 90995.702 | N7: =M7*(1+Summary!P7) -> 93270.594 | O7: =D7*(1+Summary!Q7) -> 83676.285 | P7: =O7*(1+Summary!R7) -> 87023.336 | Q7: =P7*(1+Summary!S7) -> 90069.153 | R7: =Q7*(1+Summary!T7) -> 92771.228 | S7: =R7*(1+Summary!U7) -> 95090.508
A8: Total BOE (MBOE) [Oil+Gas/6+NGL] | B8: ='Operating Metrics'!D6 -> 163413 | C8: ='Operating Metrics'!E6 -> 218972 | D8: ='Operating Metrics'!F6 -> 336178 | E8: =E5+E6/6+E7 -> 350450.45 | F8: =F5+F6/6+F7 -> 362272.57 | G8: =G5+G6/6+G7 -> 371733.72 | H8: =H5+H6/6+H7 -> 379593.16 | I8: =I5+I6/6+I7 -> 386164.33 | J8: =J5+J6/6+J7 -> 352932.07 | K8: =K5+K6/6+K7 -> 367424.18 | L8: =L5+L6/6+L7 -> 379277.68 | ... S8: =S5+S6/6+S7 -> 408029.56
A10: REVENUES ($M)
A11: Oil Sales | B11: ='Income Statement'!E4 -> 7279 | C11: ='Income Statement'!F4 -> 9067 | D11: ='Income Statement'!G4 -> 11621 | E11: =E5*Summary!G10/1000 -> 13336.522 | F11: =F5*Summary!H10/1000 -> 13194.88 | G11: =G5*Summary!I10/1000 -> 12774.383 | H11: =H5*Summary!J10/1000 -> 13029.87 | I11: =I5*Summary!K10/1000 -> 13321.124 | J11: =J5*Summary!L10/1000 -> 15473.355 | K11: =K5*Summary!M10/1000 -> 14184.043 | L11: =L5*Summary!N10/1000 -> 14138.09 | ... S11: =S5*Summary!U10/1000 -> 16067.312
A12: Natural Gas Sales | B12: ='Income Statement'!E5 -> 262 | C12: ='Income Statement'!F5 -> 89 | D12: ='Income Statement'!G5 -> 400 | E12: =E6*Summary!G11/1000 -> 633.13261 | F12: =F6*Summary!H11/1000 -> 715.93596 | G12: =G6*Summary!I11/1000 -> 740.99372 | H12: =H6*Summary!J11/1000 -> 868.49575 | I12: =I6*Summary!K11/1000 -> 890.20814 | J12: =J6*Summary!L11/1000 -> 868.74913 | K12: =K6*Summary!M11/1000 -> 937.10972 | L12: =L6*Summary!N11/1000 -> 1005.6982 | ... S12: =S6*Summary!U11/1000 -> 1754.6527
A13: NGL Sales | B13: ='Income Statement'!E6 -> 687 | C13: ='Income Statement'!F6 -> 944 | D13: ='Income Statement'!G6 -> 1432 | E13: =E7*Summary!G12/1000 -> 1532.813 | F13: =F7*Summary!H12/1000 -> 1495.9939 | G13: =G7*Summary!I12/1000 -> 1443.102 | H13: =H7*Summary!J12/1000 -> 1464.7485 | I13: =I7*Summary!K12/1000 -> 1497.2411 | J13: =J7*Summary!L12/1000 -> 1790.8153 | K13: =K7*Summary!M12/1000 -> 1637.6899 | L13: =L7*Summary!N12/1000 -> 1633.5016 | ... S13: =S7*Summary!U12/1000 -> 1854.2649
A14: E&P Revenue (excl. purchased oil) | B14: ='Income Statement'!E4+'Income Statement'!E5+'Income Statement'!E6 -> 8228 | C14: ='Income Statement'!F4+'Income Statement'!F5+'Income Statement'!F6 -> 10100 | D14: ='Income Statement'!G4+'Income Statement'!G5+'Income Statement'!G6 -> 13453 | E14: =E11+E12+E13 -> 15502.468 | F14: =F11+F12+F13 -> 15406.81 | G14: =G11+G12+G13 -> 14958.478 | H14: =H11+H12+H13 -> 15363.115 | I14: =I11+I12+I13 -> 15708.573 | J14: =J11+J12+J13 -> 18132.92 | K14: =K11+K12+K13 -> 16758.842 | L14: =L11+L12+L13 -> 16777.29 | ... S14: =S11+S12+S13 -> 19676.229
A15: Purchased Oil Revenue (pass-through) | B15: ='Income Statement'!E7 -> 111 | C15: ='Income Statement'!F7 -> 923 | D15: ='Income Statement'!G7 -> 1476 | E15: =D15 -> 1476 | F15: =D15 -> 1476 | G15: =D15 -> 1476 | H15: =D15 -> 1476 | I15: =D15 -> 1476 | J15: =D15 -> 1476 | K15: =D15 -> 1476 | L15: =D15 -> 1476 | M15: =D15 -> 1476 | N15: =D15 -> 1476 | O15: =D15 -> 1476 | P15: =D15 -> 1476 | Q15: =D15 -> 1476 | R15: =D15 -> 1476 | S15: =D15 -> 1476
A16: Total Revenue | B16: ='Income Statement'!E8 -> 8339 | C16: ='Income Statement'!F8 -> 11023 | D16: ='Income Statement'!G8 -> 14929 | E16: =E14+E15 -> 16978.468 | F16: =F14+F15 -> 16882.81 | G16: =G14+G15 -> 16434.478 | H16: =H14+H15 -> 16839.115 | I16: =I14+I15 -> 17184.573 | J16: =J14+J15 -> 19608.92 | K16: =K14+K15 -> 18234.842 | L16: =L14+L15 -> 18253.29 | ... S16: =S14+S15 -> 21152.229
A18: COST OF GOODS SOLD ($M)
A19: Lease Operating Expenses (LOE) | B19: ='Income Statement'!E11 -> 872 | C19: ='Income Statement'!F11 -> 1286 | D19: ='Income Statement'!G11 -> 1865 | E19: =E8*Summary!G14/1000 -> 1927.4775 | F19: =F8*Summary!H14/1000 -> 1974.3855 | G19: =G8*Summary!I14/1000 -> 2007.3621 | H19: =H8*Summary!J14/1000 -> 2030.8234 | I19: =I8*Summary!K14/1000 -> 2046.6709 | J19: =J8*Summary!L14/1000 -> 1941.1264 | K19: =K8*Summary!M14/1000 -> 2002.4618 | L19: =L8*Summary!N14/1000 -> 2048.0995 | ... S19: =S8*Summary!U14/1000 -> 2162.5567
A20: Production & Ad Valorem Taxes | B20: ='Income Statement'!E12 -> 525 | C20: ='Income Statement'!F12 -> 638 | D20: ='Income Statement'!G12 -> 851 | E20: =E8*Summary!G15/1000 -> 999.36238 | F20: =F8*Summary!H15/1000 -> 988.49006 | G20: =G8*Summary!I15/1000 -> 959.25887 | H20: =H8*Summary!J15/1000 -> 979.54015 | I20: =I8*Summary!K15/1000 -> 1003.5492 | J20: =J8*Summary!L15/1000 -> 1158.8832 | K20: =K8*Summary!M15/1000 -> 1065.999 | L20: =L8*Summary!N15/1000 -> 1065.6068 | ... S20: =S8*Summary!U15/1000 -> 1214.908
A21: Gathering, Processing & Transportation | B21: ='Income Statement'!E13 -> 287 | C21: ='Income Statement'!F13 -> 356 | D21: ='Income Statement'!G13 -> 515 | E21: =E8*Summary!G16/1000 -> 532.68469 | F21: =F8*Summary!H16/1000 -> 543.40886 | G21: =G8*Summary!I16/1000 -> 550.16591 | H21: =H8*Summary!J16/1000 -> 554.20601 | I21: =I8*Summary!K16/1000 -> 556.07663 | J21: =J8*Summary!L16/1000 -> 536.45675 | K21: =K8*Summary!M16/1000 -> 551.13628 | L21: =L8*Summary!N16/1000 -> 561.33097 | ... S21: =S8*Summary!U16/1000 -> 587.56256
A22: E&P COGS Subtotal | B22: ='Income Statement'!E11+'Income Statement'!E12+'Income Statement'!E13 -> 1684 | C22: ='Income Statement'!F11+'Income Statement'!F12+'Income Statement'!F13 -> 2280 | D22: ='Income Statement'!G11+'Income Statement'!G12+'Income Statement'!G13 -> 3231 | E22: =E19+E20+E21 -> 3459.5246 | F22: =F19+F20+F21 -> 3506.2845 | G22: =G19+G20+G21 -> 3516.7869 | H22: =H19+H20+H21 -> 3564.5696 | I22: =I19+I20+I21 -> 3606.2967 | J22: =J19+J20+J21 -> 3636.4663 | K22: =K19+K20+K21 -> 3619.597 | L22: =L19+L20+L21 -> 3675.0373 | ... S22: =S19+S20+S21 -> 3965.0272
A23: Purchased Oil Expense (pass-through) | B23: ='Income Statement'!E14 -> 111 | C23: ='Income Statement'!F14 -> 921 | D23: ='Income Statement'!G14 -> 1474 | E23: =E15 -> 1476 | F23: =F15 -> 1476 | G23: =G15 -> 1476 | H23: =H15 -> 1476 | I23: =I15 -> 1476 | J23: =J15 -> 1476 | K23: =K15 -> 1476 | L23: =L15 -> 1476 | ... S23: =S15 -> 1476
A24: Total COGS | B24: ='Income Statement'!E15 -> 1795 | C24: ='Income Statement'!F15 -> 3201 | D24: ='Income Statement'!G15 -> 4705 | E24: =E22+E23 -> 4935.5246 | F24: =F22+F23 -> 4982.2845 | G24: =G22+G23 -> 4992.7869 | H24: =H22+H23 -> 5040.5696 | I24: =I22+I23 -> 5082.2967 | J24: =J22+J23 -> 5112.4663 | K24: =K22+K23 -> 5095.597 | L24: =L22+L23 -> 5151.0373 | ... S24: =S22+S23 -> 5441.0272
A26: Gross Profit | B26: ='Income Statement'!E17 -> 6544 | C26: ='Income Statement'!F17 -> 7822 | D26: ='Income Statement'!G17 -> 10224 | E26: =E16-E24 -> 12042.944 | F26: =F16-F24 -> 11900.525 | G26: =G16-G24 -> 11441.692 | H26: =H16-H24 -> 11798.545 | I26: =I16-I24 -> 12102.276 | J26: =J16-J24 -> 14496.454 | K26: =K16-K24 -> 13139.245 | L26: =L16-L24 -> 13102.253 | ... S26: =S16-S24 -> 15711.202
A27: Other Operating Income | B27: ='Income Statement'!E20 -> 73 | C27: ='Income Statement'!F20 -> 43 | D27: ='Income Statement'!G20 -> 97 | E27: =E28*E16 -> 108.39282 | F27: =F28*F16 -> 107.78212 | G27: =G28*G16 -> 104.91992 | H27: =H28*H16 -> 107.50317 | I27: =I28*I16 -> 109.70862 | J27: =J28*J16 -> 125.18598 | K27: =K28*K16 -> 116.41368 | L27: =L28*L16 -> 116.53145 | ... S27: =S28*S16 -> 135.03867
A28: Other Operating Income % of Total Revenue | B28: =B27/B16 -> 0.0087540472 | C28: =C27/C16 -> 0.0039009344 | D28: =D27/D16 -> 0.0064974211 | E28: =AVERAGE(B28:D28) -> 0.0063841343 | F28: =$E$28 -> 0.0063841343 | G28: =$E$28 -> 0.0063841343 | H28: =$E$28 -> 0.0063841343 | I28: =$E$28 -> 0.0063841343 | J28: =$E$28 -> 0.0063841343 | K28: =$E$28 -> 0.0063841343 | L28: =$E$28 -> 0.0063841343 | M28: =$E$28 -> 0.0063841343 | ... S28: =$E$28 -> 0.0063841343
A30: OPERATING EXPENSES ($M)
A31: Depreciation, Depletion & Amortization | B31: ='Income Statement'!E24 -> 1746 | C31: ='Income Statement'!F24 -> 2850 | D31: ='Income Statement'!G24 -> 5038 | E31: =E8*Summary!G19/1000 -> 5256.7568 | F31: =F8*Summary!H19/1000 -> 5434.0886 | G31: =G8*Summary!I19/1000 -> 5576.0058 | H31: =H8*Summary!J19/1000 -> 5693.8974 | I31: =I8*Summary!K19/1000 -> 5792.4649 | J31: =J8*Summary!L19/1000 -> 5293.981 | K31: =K8*Summary!M19/1000 -> 5511.3628 | L31: =L8*Summary!N19/1000 -> 5689.1652 | ... S31: =S8*Summary!U19/1000 -> 6120.4434
A32: General & Administrative (cash G&A basis) | B32: ='Income Statement'!E26 -> 150 | C32: ='Income Statement'!F26 -> 213 | D32: ='Income Statement'!G26 -> 288 | E32: =E8*Summary!G17/1000 -> 210.27027 | F32: =F8*Summary!H17/1000 -> 210.11809 | G32: =G8*Summary!I17/1000 -> 208.17088 | H32: =H8*Summary!J17/1000 -> 204.98031 | I32: =I8*Summary!K17/1000 -> 200.80545 | J32: =J8*Summary!L17/1000 -> 211.75924 | K32: =K8*Summary!M17/1000 -> 213.10603 | L32: =L8*Summary!N17/1000 -> 212.3955 | ... S32: =S8*Summary!U17/1000 -> 212.17537
A33: Other Operating Expenses, net | B33: ='Income Statement'!E27 -> 151 | C33: ='Income Statement'!F27 -> 406 | D33: ='Income Statement'!G27 -> 77 | E33: =AVERAGE(B33,D33) -> 114 | F33: =$E$33 -> 114 | G33: =$E$33 -> 114 | H33: =$E$33 -> 114 | I33: =$E$33 -> 114 | J33: =$E$33 -> 114 | K33: =$E$33 -> 114 | L33: =$E$33 -> 114 | M33: =$E$33 -> 114 | ... S33: =$E$33 -> 114
A34: Total Operating Expenses | B34: ='Income Statement'!E28 -> 2047 | C34: ='Income Statement'!F28 -> 3469 | D34: ='Income Statement'!G28 -> 9055 | E34: =E31+E32+E33 -> 5581.0271 | F34: =F31+F32+F33 -> 5758.2067 | G34: =G31+G32+G33 -> 5898.1767 | H34: =H31+H32+H33 -> 6012.8777 | I34: =I31+I32+I33 -> 6107.2703 | J34: =J31+J32+J33 -> 5619.7403 | K34: =K31+K32+K33 -> 5838.4688 | L34: =L31+L32+L33 -> 6015.5607 | ... S34: =S31+S32+S33 -> 6446.6187
A36: EBIT (Operating Income, excl. impairment) | B36: ='Income Statement'!E30 -> 4570 | C36: ='Income Statement'!F30 -> 4396 | D36: ='Income Statement'!G30 -> 1266 | E36: =E26+E27-E34 -> 6570.3093 | F36: =F26+F27-F34 -> 6250.1008 | G36: =G26+G27-G34 -> 5648.4347 | H36: =H26+H27-H34 -> 5893.1705 | I36: =I26+I27-I34 -> 6104.7147 | J36: =J26+J27-J34 -> 9001.8993 | K36: =K26+K27-K34 -> 7417.19 | L36: =L26+L27-L34 -> 7203.2233 | ... S36: =S26+S27-S34 -> 9399.6222
A38: Interest Expense, net | B38: ='Income Statement'!E32 -> -159 | C38: ='Income Statement'!F32 -> -135 | D38: ='Income Statement'!G32 -> -244 | E38: =-E39*(Forecast_BS!E22+Forecast_BS!E29) -> -221.62335 | F38: =-F39*(Forecast_BS!F22+Forecast_BS!F29) -> -196.02977 | G38: =-G39*(Forecast_BS!G22+Forecast_BS!G29) -> -170.43619 | H38: =-H39*(Forecast_BS!H22+Forecast_BS!H29) -> -144.84261 | I38: =-I39*(Forecast_BS!I22+Forecast_BS!I29) -> -119.24903 | J38: =-J39*(Forecast_BS!J22+Forecast_BS!J29) -> -221.62335 | K38: =-K39*(Forecast_BS!K22+Forecast_BS!K29) -> -196.02977 | L38: =-L39*(Forecast_BS!L22+Forecast_BS!L29) -> -170.43619 | ... S38: =-S39*(Forecast_BS!S22+Forecast_BS!S29) -> -119.24903
A39: interest rate | B39: =-B38/Forecast_BS!B29 -> 0.023942177 | C39: =-C38/(Forecast_BS!C22+Forecast_BS!C29) -> 0.010404624 | D39: =-D38/(Forecast_BS!D22+Forecast_BS!D29) -> 0.016840362 | E39: =AVERAGE(B39:D39) -> 0.017062388 | F39: =$E$39 -> 0.017062388 | G39: =$E$39 -> 0.017062388 | H39: =$E$39 -> 0.017062388 | I39: =$E$39 -> 0.017062388 | J39: =$E$39 -> 0.017062388 | K39: =$E$39 -> 0.017062388 | L39: =$E$39 -> 0.017062388 | M39: =$E$39 -> 0.017062388 | ... S39: =$E$39 -> 0.017062388
A40: Other Non-Operating Income (normalized) | B40: ='Income Statement'!E35 -> 100 | C40: ='Income Statement'!F35 -> 101 | D40: ='Income Statement'!G35 -> 455 | E40: =100 -> 100 | F40: =100 -> 100 | G40: =100 -> 100 | H40: =100 -> 100 | I40: =100 -> 100 | J40: =100 -> 100 | K40: =100 -> 100 | L40: =100 -> 100 | ... S40: =100 -> 100
A42: Pretax Income | B42: ='Income Statement'!E40 -> 4248 | C42: ='Income Statement'!F40 -> 4501 | D42: ='Income Statement'!G40 -> 1874 | E42: =E36+E38+E40 -> 6448.6859 | F42: =F36+F38+F40 -> 6154.0711 | G42: =G36+G38+G40 -> 5577.9985 | H42: =H36+H38+H40 -> 5848.3279 | I42: =I36+I38+I40 -> 6085.4657 | J42: =J36+J38+J40 -> 8880.276 | K42: =K36+K38+K40 -> 7321.1603 | L42: =L36+L38+L40 -> 7132.7871 | ... S42: =S36+S38+S40 -> 9380.3731
A43: Income Tax Expense | B43: ='Income Statement'!E42 -> 912 | C43: ='Income Statement'!F42 -> 800 | D43: ='Income Statement'!G42 -> 327 | E43: =IF(E42>0,E42*Summary!G23,0) -> 1289.7372 | F43: =IF(F42>0,F42*Summary!H23,0) -> 1230.8142 | G43: =IF(G42>0,G42*Summary!I23,0) -> 1115.5997 | H43: =IF(H42>0,H42*Summary!J23,0) -> 1169.6656 | I43: =IF(I42>0,I42*Summary!K23,0) -> 1217.0931 | J43: =IF(J42>0,J42*Summary!L23,0) -> 1776.0552 | K43: =IF(K42>0,K42*Summary!M23,0) -> 1464.2321 | L43: =IF(L42>0,L42*Summary!N23,0) -> 1426.5574 | ... S43: =IF(S42>0,S42*Summary!U23,0) -> 1876.0746
A44: Net Income | B44: ='Income Statement'!E44 -> 3336 | C44: ='Income Statement'!F44 -> 3701 | D44: ='Income Statement'!G44 -> 1547 | E44: =E42-E43 -> 5158.9488 | F44: =F42-F43 -> 4923.2569 | G44: =G42-G43 -> 4462.3988 | H44: =H42-H43 -> 4678.6623 | I44: =I42-I43 -> 4868.3725 | J44: =J42-J43 -> 7104.2208 | K44: =K42-K43 -> 5856.9282 | L44: =L42-L43 -> 5706.2297 | ... S44: =S42-S43 -> 7504.2985
A45: Non-Controlling Interest (NCI) | B45: ='Income Statement'!E45 -> 193 | C45: ='Income Statement'!F45 -> 363 | D45: ='Income Statement'!G45 -> -117 | E45: =E14*E46 -> 310.04936 | F45: =F14*F46 -> 308.1362 | G45: =G14*G46 -> 299.16957 | H45: =H14*H46 -> 307.26229 | I45: =I14*I46 -> 314.17146 | J45: =J14*J46 -> 362.6584 | K45: =K14*K46 -> 335.17684 | L45: =L14*L46 -> 335.5458 | ... S45: =S14*S46 -> 393.52459
A46: Non-Controlling Interest (NCI) % of E&P Rev | B46: =B45/B14 -> 0.02345649 | C46: =C45/C14 -> 0.035940594 | D46: =D45/D14 -> -0.0086969449 | E46: 0.02 | F46: =$E$46 -> 0.02 | G46: =$E$46 -> 0.02 | H46: =$E$46 -> 0.02 | I46: =$E$46 -> 0.02 | J46: =$E$46 -> 0.02 | K46: =$E$46 -> 0.02 | L46: =$E$46 -> 0.02 | M46: =$E$46 -> 0.02 | ... S46: =$E$46 -> 0.02
A47: Net Income Attributable to FANG | B47: ='Income Statement'!E46 -> 3143 | C47: ='Income Statement'!F46 -> 3338 | D47: ='Income Statement'!G46 -> 1664 | E47: =E44-E45 -> 4848.8994 | F47: =F44-F45 -> 4615.1207 | G47: =G44-G45 -> 4163.2293 | H47: =H44-H45 -> 4371.4 | I47: =I44-I45 -> 4554.2011 | J47: =J44-J45 -> 6741.5624 | K47: =K44-K45 -> 5521.7514 | L47: =L44-L45 -> 5370.6839 | ... S47: =S44-S45 -> 7110.7739
...

Sheet Forecast_BS
A1: DIAMONDBACK ENERGY (FANG) — FORECAST BALANCE SHEET ($M )
B2: HISTORICAL | E2: BEAR | J2: BASE | O2: BULL
B3: 2023A | C3: 2024A | D3: 2025A | E3: 2026E | F3: 2027E | G3: 2028E | H3: 2029E | I3: 2030E | J3: 2026E | K3: 2027E | L3: 2028E | M3: 2029E | N3: 2030E | O3: 2026E | P3: 2027E | Q3: 2028E | R3: 2029E | S3: 2030E
A4: A. CURRENT ASSETS ($M)
A5: Cash & Cash Equivalents [← CF back-fill] | B5: ='Balance Sheet'!E5 -> 582 | C5: ='Balance Sheet'!F5 -> 161 | D5: ='Balance Sheet'!G5 -> 104 | E5: =IF(ISBLANK(Forecast_CF!E36),0,Forecast_CF!E36) -> 566.16283 | F5: =IF(ISBLANK(Forecast_CF!F36),0,Forecast_CF!F36) -> 1607.9317 | G5: =IF(ISBLANK(Forecast_CF!G36),0,Forecast_CF!G36) -> 2735.7277 | H5: =IF(ISBLANK(Forecast_CF!H36),0,Forecast_CF!H36) -> 4245.5636 | I5: =IF(ISBLANK(Forecast_CF!I36),0,Forecast_CF!I36) -> 5872.5448 | J5: =IF(ISBLANK(Forecast_CF!J36),0,Forecast_CF!J36) -> 1778.0841 | K5: =IF(ISBLANK(Forecast_CF!K36),0,Forecast_CF!K36) -> 3367.8839 | L5: =IF(ISBLANK(Forecast_CF!L36),0,Forecast_CF!L36) -> 5315.1402 | ... S5: =IF(ISBLANK(Forecast_CF!S36),0,Forecast_CF!S36) -> 14833.15
A6: Oil, Gas & NGL Receivables (28-day DSO) | B6: ='Balance Sheet'!E9 -> 654 | C6: ='Balance Sheet'!F9 -> 1387 | D6: ='Balance Sheet'!G9 -> 1128 | E6: =Forecast_IS!E14/365*28 -> 1189.2304 | F6: =Forecast_IS!F14/365*28 -> 1181.8923 | G6: =Forecast_IS!G14/365*28 -> 1147.4997 | H6: =Forecast_IS!H14/365*28 -> 1178.5403 | I6: =Forecast_IS!I14/365*28 -> 1205.0412 | J6: =Forecast_IS!J14/365*28 -> 1391.0185 | K6: =Forecast_IS!K14/365*28 -> 1285.6098 | L6: =Forecast_IS!L14/365*28 -> 1287.025 | ... S6: =Forecast_IS!S14/365*28 -> 1509.4094
A7: Joint-Interest & Other Receivables | B7: ='Balance Sheet'!E8 -> 192 | C7: ='Balance Sheet'!F8 -> 198 | D7: ='Balance Sheet'!G8 -> 258 | E7: ='Balance Sheet'!G8 -> 258 | F7: ='Balance Sheet'!G8 -> 258 | G7: ='Balance Sheet'!G8 -> 258 | H7: ='Balance Sheet'!G8 -> 258 | I7: ='Balance Sheet'!G8 -> 258 | J7: ='Balance Sheet'!G8 -> 258 | K7: ='Balance Sheet'!G8 -> 258 | L7: ='Balance Sheet'!G8 -> 258 | M7: ='Balance Sheet'!G8 -> 258 | N7: ='Balance Sheet'!G8 -> 258 | O7: ='Balance Sheet'!G8 -> 258 | P7: ='Balance Sheet'!G8 -> 258 | Q7: ='Balance Sheet'!G8 -> 258 | R7: ='Balance Sheet'!G8 -> 258 | S7: ='Balance Sheet'!G8 -> 258
A8: Inventories | B8: ='Balance Sheet'!E10 -> 63 | C8: ='Balance Sheet'!F10 -> 116 | D8: ='Balance Sheet'!G10 -> 86 | E8: ='Balance Sheet'!G10 -> 86 | F8: ='Balance Sheet'!G10 -> 86 | G8: ='Balance Sheet'!G10 -> 86 | H8: ='Balance Sheet'!G10 -> 86 | I8: ='Balance Sheet'!G10 -> 86 | J8: ='Balance Sheet'!G10 -> 86 | K8: ='Balance Sheet'!G10 -> 86 | L8: ='Balance Sheet'!G10 -> 86 | M8: ='Balance Sheet'!G10 -> 86 | N8: ='Balance Sheet'!G10 -> 86 | O8: ='Balance Sheet'!G10 -> 86 | P8: ='Balance Sheet'!G10 -> 86 | Q8: ='Balance Sheet'!G10 -> 86 | R8: ='Balance Sheet'!G10 -> 86 | S8: ='Balance Sheet'!G10 -> 86
A9: Prepaid & Other Current Assets | B9: ='Balance Sheet'!E11 -> 127 | C9: ='Balance Sheet'!F11 -> 245 | D9: ='Balance Sheet'!G11 -> 337 | E9: ='Balance Sheet'!G11 -> 337 | F9: ='Balance Sheet'!G11 -> 337 | G9: ='Balance Sheet'!G11 -> 337 | H9: ='Balance Sheet'!G11 -> 337 | I9: ='Balance Sheet'!G11 -> 337 | J9: ='Balance Sheet'!G11 -> 337 | K9: ='Balance Sheet'!G11 -> 337 | L9: ='Balance Sheet'!G11 -> 337 | M9: ='Balance Sheet'!G11 -> 337 | N9: ='Balance Sheet'!G11 -> 337 | O9: ='Balance Sheet'!G11 -> 337 | P9: ='Balance Sheet'!G11 -> 337 | Q9: ='Balance Sheet'!G11 -> 337 | R9: ='Balance Sheet'!G11 -> 337 | S9: ='Balance Sheet'!G11 -> 337
A10: Total Current Assets | B10: ='Balance Sheet'!E12 -> 1621 | C10: ='Balance Sheet'!F12 -> 2110 | D10: ='Balance Sheet'!G12 -> 1915 | E10: =E5+E6+E7+E8+E9 -> 2436.3933 | F10: =F5+F6+F7+F8+F9 -> 3470.8239 | G10: =G5+G6+G7+G8+G9 -> 4564.2275 | H10: =H5+H6+H7+H8+H9 -> 6105.1039 | I10: =I5+I6+I7+I8+I9 -> 7758.586 | J10: =J5+J6+J7+J8+J9 -> 3850.1026 | K10: =K5+K6+K7+K8+K9 -> 5334.4937 | L10: =L5+L6+L7+L8+L9 -> 7283.1651 | ... S10: =S5+S6+S7+S8+S9 -> 17023.56
A12: B. LONG-TERM ASSETS ($M)
A13: Gross Oil & Gas Properties | B13: ='Balance Sheet'!E14 -> 42430 | C13: ='Balance Sheet'!F14 -> 82240 | D13: ='Balance Sheet'!G14 -> 95529 | E13: =D13+Summary!G21 -> 99429 | F13: =E13+Summary!H21 -> 103446 | G13: =F13+Summary!I21 -> 107543.34 | H13: =G13+Summary!J21 -> 111722.63 | I13: =H13+Summary!K21 -> 115985.5 | J13: =D13+Summary!L21 -> 99429 | K13: =J13+Summary!M21 -> 103446 | L13: =K13+Summary!N21 -> 107543.34 | M13: =L13+Summary!O21 -> 111722.63 | N13: =M13+Summary!P21 -> 115985.5 | O13: =D13+Summary!Q21 -> 99429 | P13: =O13+Summary!R21 -> 103446 | Q13: =P13+Summary!S21 -> 107543.34 | R13: =Q13+Summary!T21 -> 111722.63 | S13: =R13+Summary!U21 -> 115985.5
A14: Other Property & Equipment | B14: ='Balance Sheet'!E15 -> 673 | C14: ='Balance Sheet'!F15 -> 1440 | D14: ='Balance Sheet'!G15 -> 874 | E14: ='Balance Sheet'!G15 -> 874 | F14: ='Balance Sheet'!G15 -> 874 | G14: ='Balance Sheet'!G15 -> 874 | H14: ='Balance Sheet'!G15 -> 874 | I14: ='Balance Sheet'!G15 -> 874 | J14: ='Balance Sheet'!G15 -> 874 | K14: ='Balance Sheet'!G15 -> 874 | L14: ='Balance Sheet'!G15 -> 874 | M14: ='Balance Sheet'!G15 -> 874 | N14: ='Balance Sheet'!G15 -> 874 | O14: ='Balance Sheet'!G15 -> 874 | P14: ='Balance Sheet'!G15 -> 874 | Q14: ='Balance Sheet'!G15 -> 874 | R14: ='Balance Sheet'!G15 -> 874 | S14: ='Balance Sheet'!G15 -> 874
A15: Accumulated DD&A (negative) | B15: ='Balance Sheet'!E16 -> -16429 | C15: ='Balance Sheet'!F16 -> -19208 | D15: ='Balance Sheet'!G16 -> -27782 | E15: =D15-Forecast_IS!E31 -> -33038.757 | F15: =E15-Forecast_IS!F31 -> -38472.845 | G15: =F15-Forecast_IS!G31 -> -44048.851 | H15: =G15-Forecast_IS!H31 -> -49742.749 | I15: =H15-Forecast_IS!I31 -> -55535.214 | J15: =D15-Forecast_IS!J31 -> -33075.981 | K15: =J15-Forecast_IS!K31 -> -38587.344 | L15: =K15-Forecast_IS!L31 -> -44276.509 | M15: =L15-Forecast_IS!M31 -> -50120.863 | N15: =M15-Forecast_IS!N31 -> -56102.343 | O15: =D15-Forecast_IS!O31 -> -33101.194 | P15: =O15-Forecast_IS!P31 -> -38665.401 | Q15: =P15-Forecast_IS!Q31 -> -44436.935 | R15: =Q15-Forecast_IS!R31 -> -50394.76 | S15: =R15-Forecast_IS!S31 -> -56515.204
A16: PP&E, Net | B16: ='Balance Sheet'!E17 -> 26674 | C16: ='Balance Sheet'!F17 -> 64472 | D16: ='Balance Sheet'!G17 -> 68621 | E16: =E13+E14+E15 -> 67264.243 | F16: =F13+F14+F15 -> 65847.155 | G16: =G13+G14+G15 -> 64368.489 | H16: =H13+H14+H15 -> 62853.878 | I16: =I13+I14+I15 -> 61324.286 | J16: =J13+J14+J15 -> 67227.019 | K16: =K13+K14+K15 -> 65732.656 | L16: =L13+L14+L15 -> 64140.831 | ... S16: =S13+S14+S15 -> 60344.296
A17: Other Long-Term Assets | B17: ='Balance Sheet'!E18 -> 706 | C17: ='Balance Sheet'!F18 -> 710 | D17: ='Balance Sheet'!G18 -> 523 | E17: ='Balance Sheet'!G18 -> 523 | F17: ='Balance Sheet'!G18 -> 523 | G17: ='Balance Sheet'!G18 -> 523 | H17: ='Balance Sheet'!G18 -> 523 | I17: ='Balance Sheet'!G18 -> 523 | J17: ='Balance Sheet'!G18 -> 523 | K17: ='Balance Sheet'!G18 -> 523 | L17: ='Balance Sheet'!G18 -> 523 | M17: ='Balance Sheet'!G18 -> 523 | N17: ='Balance Sheet'!G18 -> 523 | O17: ='Balance Sheet'!G18 -> 523 | P17: ='Balance Sheet'!G18 -> 523 | Q17: ='Balance Sheet'!G18 -> 523 | R17: ='Balance Sheet'!G18 -> 523 | S17: ='Balance Sheet'!G18 -> 523
A18: TOTAL ASSETS | B18: ='Balance Sheet'!E19 -> 29001 | C18: ='Balance Sheet'!F19 -> 67292 | D18: ='Balance Sheet'!G19 -> 71059 | E18: =E10+E16+E17 -> 70223.636 | F18: =F10+F16+F17 -> 69840.979 | G18: =G10+G16+G17 -> 69455.716 | H18: =H10+H16+H17 -> 69481.982 | I18: =I10+I16+I17 -> 69605.872 | J18: =J10+J16+J17 -> 71600.122 | K18: =K10+K16+K17 -> 71590.15 | L18: =L10+L16+L17 -> 71946.996 | ... S18: =S10+S16+S17 -> 77890.855
A20: C. CURRENT LIABILITIES ($M)
A21: Accounts Payable & Accrued Capex (60-day) | B21: ='Balance Sheet'!E23 -> 754 | C21: ='Balance Sheet'!F23 -> 943 | D21: ='Balance Sheet'!G23 -> 1168 | E21: =(Forecast_IS!E22+Forecast_IS!E21+Forecast_IS!E20)/365*60+Summary!G21/12 -> 1145.5323 | F21: =(Forecast_IS!F22+Forecast_IS!F21+Forecast_IS!F20)/365*60+Summary!H21/12 -> 1162.9445 | G21: =(Forecast_IS!G22+Forecast_IS!G21+Forecast_IS!G20)/365*60+Summary!I21/12 -> 1167.6716 | H21: =(Forecast_IS!H22+Forecast_IS!H21+Forecast_IS!H20)/365*60+Summary!J21/12 -> 1186.3532 | I21: =(Forecast_IS!I22+Forecast_IS!I21+Forecast_IS!I20)/365*60+Summary!K21/12 -> 1204.4321 | J21: =(Forecast_IS!J22+Forecast_IS!J21+Forecast_IS!J20)/365*60+Summary!L21/12 -> 1201.4613 | K21: =(Forecast_IS!K22+Forecast_IS!K21+Forecast_IS!K20)/365*60+Summary!M21/12 -> 1195.5827 | L21: =(Forecast_IS!L22+Forecast_IS!L21+Forecast_IS!L20)/365*60+Summary!N21/12 -> 1213.0025 | ... S21: =(Forecast_IS!S22+Forecast_IS!S21+Forecast_IS!S20)/365*60+Summary!U21/12 -> 1303.3212
A22: Current Portion of Long-Term Debt | B22: ='Balance Sheet'!E24 -> 0 | C22: ='Balance Sheet'!F24 -> 900 | D22: ='Balance Sheet'!G24 -> 763 | E22: =$D$22 -> 763 | F22: =$D$22 -> 763 | G22: =$D$22 -> 763 | H22: =$D$22 -> 763 | I22: =$D$22 -> 763 | J22: =$D$22 -> 763 | K22: =$D$22 -> 763 | L22: =$D$22 -> 763 | ... S22: =$D$22 -> 763
A23: Other Accrued Liabilities | B23: ='Balance Sheet'!E25 -> 475 | C23: ='Balance Sheet'!F25 -> 1020 | D23: ='Balance Sheet'!G25 -> 1108 | E23: ='Balance Sheet'!G25 -> 1108 | F23: ='Balance Sheet'!G25 -> 1108 | G23: ='Balance Sheet'!G25 -> 1108 | H23: ='Balance Sheet'!G25 -> 1108 | I23: ='Balance Sheet'!G25 -> 1108 | J23: ='Balance Sheet'!G25 -> 1108 | K23: ='Balance Sheet'!G25 -> 1108 | L23: ='Balance Sheet'!G25 -> 1108 | M23: ='Balance Sheet'!G25 -> 1108 | N23: ='Balance Sheet'!G25 -> 1108 | O23: ='Balance Sheet'!G25 -> 1108 | P23: ='Balance Sheet'!G25 -> 1108 | Q23: ='Balance Sheet'!G25 -> 1108 | R23: ='Balance Sheet'!G25 -> 1108 | S23: ='Balance Sheet'!G25 -> 1108
A24: Revenues & Royalties Payable (34-day) | B24: ='Balance Sheet'!E26 -> 764 | C24: ='Balance Sheet'!F26 -> 1491 | D24: ='Balance Sheet'!G26 -> 1397 | E24: =Forecast_IS!E14/365*34 -> 1444.0655 | F24: =Forecast_IS!F14/365*34 -> 1435.1549 | G24: =Forecast_IS!G14/365*34 -> 1393.3925 | H24: =Forecast_IS!H14/365*34 -> 1431.0846 | I24: =Forecast_IS!I14/365*34 -> 1463.2643 | J24: =Forecast_IS!J14/365*34 -> 1689.0939 | K24: =Forecast_IS!K14/365*34 -> 1561.0976 | L24: =Forecast_IS!L14/365*34 -> 1562.816 | ... S24: =Forecast_IS!S14/365*34 -> 1832.8542
A25: Income Taxes Payable | B25: ='Balance Sheet'!E28 -> 29 | C25: ='Balance Sheet'!F28 -> 414 | D25: ='Balance Sheet'!G28 -> 149 | E25: ='Balance Sheet'!G28 -> 149 | F25: ='Balance Sheet'!G28 -> 149 | G25: ='Balance Sheet'!G28 -> 149 | H25: ='Balance Sheet'!G28 -> 149 | I25: ='Balance Sheet'!G28 -> 149 | J25: ='Balance Sheet'!G28 -> 149 | K25: ='Balance Sheet'!G28 -> 149 | L25: ='Balance Sheet'!G28 -> 149 | M25: ='Balance Sheet'!G28 -> 149 | N25: ='Balance Sheet'!G28 -> 149 | O25: ='Balance Sheet'!G28 -> 149 | P25: ='Balance Sheet'!G28 -> 149 | Q25: ='Balance Sheet'!G28 -> 149 | R25: ='Balance Sheet'!G28 -> 149 | S25: ='Balance Sheet'!G28 -> 149
A26: Total Current Liabilities | B26: ='Balance Sheet'!E29 -> 2108 | C26: ='Balance Sheet'!F29 -> 4811 | D26: ='Balance Sheet'!G29 -> 4600 | E26: =E21+E22+E23+E24+E25 -> 4609.5978 | F26: =F21+F22+F23+F24+F25 -> 4618.0994 | G26: =G21+G22+G23+G24+G25 -> 4581.0641 | H26: =H21+H22+H23+H24+H25 -> 4637.4378 | I26: =I21+I22+I23+I24+I25 -> 4687.6965 | J26: =J21+J22+J23+J24+J25 -> 4910.5552 | K26: =K21+K22+K23+K24+K25 -> 4776.6803 | L26: =L21+L22+L23+L24+L25 -> 4795.8186 | ... S26: =S21+S22+S23+S24+S25 -> 5156.1755
A28: D. LONG-TERM LIABILITIES ($M)
A29: Long-Term Debt [held at 2025A — QC note] | B29: ='Balance Sheet'!E30 -> 6641 | C29: ='Balance Sheet'!F30 -> 12075 | D29: ='Balance Sheet'!G30 -> 13726 | E29: =D29+Forecast_CF!E24+Forecast_CF!E25 -> 12226 | F29: =E29+Forecast_CF!F24+Forecast_CF!F25 -> 10726 | G29: =F29+Forecast_CF!G24+Forecast_CF!G25 -> 9226 | H29: =G29+Forecast_CF!H24+Forecast_CF!H25 -> 7726 | I29: =H29+Forecast_CF!I24+Forecast_CF!I25 -> 6226 | J29: =D29+Forecast_CF!J24+Forecast_CF!J25 -> 12226 | K29: =J29+Forecast_CF!K24+Forecast_CF!K25 -> 10726 | L29: =K29+Forecast_CF!L24+Forecast_CF!L25 -> 9226 | M29: =L29+Forecast_CF!M24+Forecast_CF!M25 -> 7726 | N29: =M29+Forecast_CF!N24+Forecast_CF!N25 -> 6226 | O29: =D29+Forecast_CF!O24+Forecast_CF!O25 -> 12226 | P29: =O29+Forecast_CF!P24+Forecast_CF!P25 -> 10726 | Q29: =P29+Forecast_CF!Q24+Forecast_CF!Q25 -> 9226 | R29: =Q29+Forecast_CF!R24+Forecast_CF!R25 -> 7726 | S29: =R29+Forecast_CF!S24+Forecast_CF!S25 -> 6226
A30: Deferred Income Taxes | B30: ='Balance Sheet'!E31 -> 2449 | C30: ='Balance Sheet'!F31 -> 9826 | D30: ='Balance Sheet'!G31 -> 9141 | E30: ='Balance Sheet'!G31 -> 9141 | F30: ='Balance Sheet'!G31 -> 9141 | G30: ='Balance Sheet'!G31 -> 9141 | H30: ='Balance Sheet'!G31 -> 9141 | I30: ='Balance Sheet'!G31 -> 9141 | J30: ='Balance Sheet'!G31 -> 9141 | K30: ='Balance Sheet'!G31 -> 9141 | L30: ='Balance Sheet'!G31 -> 9141 | M30: ='Balance Sheet'!G31 -> 9141 | N30: ='Balance Sheet'!G31 -> 9141 | O30: ='Balance Sheet'!G31 -> 9141 | P30: ='Balance Sheet'!G31 -> 9141 | Q30: ='Balance Sheet'!G31 -> 9141 | R30: ='Balance Sheet'!G31 -> 9141 | S30: ='Balance Sheet'!G31 -> 9141
A31: Other Long-Term Liabilities | B31: ='Balance Sheet'!E32 -> 373 | C31: ='Balance Sheet'!F32 -> 718 | D31: ='Balance Sheet'!G32 -> 625 | E31: ='Balance Sheet'!G32 -> 625 | F31: ='Balance Sheet'!G32 -> 625 | G31: ='Balance Sheet'!G32 -> 625 | H31: ='Balance Sheet'!G32 -> 625 | I31: ='Balance Sheet'!G32 -> 625 | J31: ='Balance Sheet'!G32 -> 625 | K31: ='Balance Sheet'!G32 -> 625 | L31: ='Balance Sheet'!G32 -> 625 | M31: ='Balance Sheet'!G32 -> 625 | N31: ='Balance Sheet'!G32 -> 625 | O31: ='Balance Sheet'!G32 -> 625 | P31: ='Balance Sheet'!G32 -> 625 | Q31: ='Balance Sheet'!G32 -> 625 | R31: ='Balance Sheet'!G32 -> 625 | S31: ='Balance Sheet'!G32 -> 625
A32: TOTAL LIABILITIES | B32: ='Balance Sheet'!E33 -> 11571 | C32: ='Balance Sheet'!F33 -> 27430 | D32: ='Balance Sheet'!G33 -> 28092 | E32: =E26+E29+E30+E31 -> 26601.598 | F32: =F26+F29+F30+F31 -> 25110.099 | G32: =G26+G29+G30+G31 -> 23573.064 | H32: =H26+H29+H30+H31 -> 22129.438 | I32: =I26+I29+I30+I31 -> 20679.696 | J32: =J26+J29+J30+J31 -> 26902.555 | K32: =K26+K29+K30+K31 -> 25268.68 | L32: =L26+L29+L30+L31 -> 23787.819 | ... S32: =S26+S29+S30+S31 -> 21148.175
B33: =B22+B29 -> 6641 | C33: =C22+C29 -> 12975 | D33: =D22+D29 -> 14489
A34: E. SHAREHOLDERS' EQUITY ($M)
A35: Common Stock | B35: ='Balance Sheet'!E36 -> 2 | C35: ='Balance Sheet'!F36 -> 3 | D35: ='Balance Sheet'!G36 -> 3 | E35: ='Balance Sheet'!G36 -> 3 | F35: ='Balance Sheet'!G36 -> 3 | G35: ='Balance Sheet'!G36 -> 3 | H35: ='Balance Sheet'!G36 -> 3 | I35: ='Balance Sheet'!G36 -> 3 | J35: ='Balance Sheet'!G36 -> 3 | K35: ='Balance Sheet'!G36 -> 3 | L35: ='Balance Sheet'!G36 -> 3 | M35: ='Balance Sheet'!G36 -> 3 | N35: ='Balance Sheet'!G36 -> 3 | O35: ='Balance Sheet'!G36 -> 3 | P35: ='Balance Sheet'!G36 -> 3 | Q35: ='Balance Sheet'!G36 -> 3 | R35: ='Balance Sheet'!G36 -> 3 | S35: ='Balance Sheet'!G36 -> 3
A36: Additional Paid-In Capital | B36: ='Balance Sheet'!E37 -> 14142 | C36: ='Balance Sheet'!F37 -> 33501 | D36: ='Balance Sheet'!G37 -> 32236 | E36: =D36+Forecast_CF!E26 -> 30136 | F36: =E36+Forecast_CF!F26 -> 28636 | G36: =F36+Forecast_CF!G26 -> 27436 | H36: =G36+Forecast_CF!H26 -> 26436 | I36: =H36+Forecast_CF!I26 -> 25436 | J36: =D36+Forecast_CF!J26 -> 30136 | K36: =E36+Forecast_CF!K26 -> 28636 | L36: =F36+Forecast_CF!L26 -> 27436 | M36: =G36+Forecast_CF!M26 -> 26436 | N36: =H36+Forecast_CF!N26 -> 25436 | O36: =D36+Forecast_CF!O26 -> 30136 | P36: =E36+Forecast_CF!P26 -> 28636 | Q36: =F36+Forecast_CF!Q26 -> 27436 | R36: =G36+Forecast_CF!R26 -> 26436 | S36: =H36+Forecast_CF!S26 -> 25436
A37: Retained Earnings | B37: ='Balance Sheet'!E38 -> 2489 | C37: ='Balance Sheet'!F38 -> 4238 | D37: ='Balance Sheet'!G38 -> 4740 | E37: =D37+Forecast_IS!E47+Forecast_CF!E27 -> 7372.5506 | F37: =E37+Forecast_IS!F47+Forecast_CF!F27 -> 9872.5787 | G37: =F37+Forecast_IS!G47+Forecast_CF!G27 -> 12118.706 | H37: =G37+Forecast_IS!H47+Forecast_CF!H27 -> 14480.094 | I37: =H37+Forecast_IS!I47+Forecast_CF!I27 -> 16942.781 | J37: =D37+Forecast_IS!J47+Forecast_CF!J27 -> 8429.5005 | K37: =J37+Forecast_IS!K47+Forecast_CF!K27 -> 11435.042 | L37: =K37+Forecast_IS!L47+Forecast_CF!L27 -> 14354.259 | M37: =L37+Forecast_IS!M47+Forecast_CF!M27 -> 17401.278 | N37: =M37+Forecast_IS!N47+Forecast_CF!N27 -> 20556.449 | O37: =D37+Forecast_IS!O47+Forecast_CF!O27 -> 9262.2334 | P37: =O37+Forecast_IS!P47+Forecast_CF!P27 -> 13024.416 | Q37: =P37+Forecast_IS!Q47+Forecast_CF!Q27 -> 16964.854 | R37: =Q37+Forecast_IS!R47+Forecast_CF!R27 -> 20730.494 | S37: =R37+Forecast_IS!S47+Forecast_CF!S27 -> 24617.328
A38: Accumulated OCI | B38: ='Balance Sheet'!E39 -> -8 | C38: ='Balance Sheet'!F39 -> -6 | D38: ='Balance Sheet'!G39 -> -7 | E38: ='Balance Sheet'!G39 -> -7 | F38: ='Balance Sheet'!G39 -> -7 | G38: ='Balance Sheet'!G39 -> -7 | H38: ='Balance Sheet'!G39 -> -7 | I38: ='Balance Sheet'!G39 -> -7 | J38: ='Balance Sheet'!G39 -> -7 | K38: ='Balance Sheet'!G39 -> -7 | L38: ='Balance Sheet'!G39 -> -7 | M38: ='Balance Sheet'!G39 -> -7 | N38: ='Balance Sheet'!G39 -> -7 | O38: ='Balance Sheet'!G39 -> -7 | P38: ='Balance Sheet'!G39 -> -7 | Q38: ='Balance Sheet'!G39 -> -7 | R38: ='Balance Sheet'!G39 -> -7 | S38: ='Balance Sheet'!G39 -> -7
A39: Total FANG Shareholders' Equity | B39: ='Balance Sheet'!E40 -> 16625 | C39: ='Balance Sheet'!F40 -> 37736 | D39: ='Balance Sheet'!G40 -> 36972 | E39: =E35+E36+E37+E38 -> 37504.551 | F39: =F35+F36+F37+F38 -> 38504.579 | G39: =G35+G36+G37+G38 -> 39550.706 | H39: =H35+H36+H37+H38 -> 40912.094 | I39: =I35+I36+I37+I38 -> 42374.781 | J39: =J35+J36+J37+J38 -> 38561.5 | K39: =K35+K36+K37+K38 -> 40067.042 | L39: =L35+L36+L37+L38 -> 41786.259 | ... S39: =S35+S36+S37+S38 -> 50049.328
A40: Non-Controlling Interests | B40: ='Balance Sheet'!E41 -> 805 | C40: ='Balance Sheet'!F41 -> 2126 | D40: ='Balance Sheet'!G41 -> 5995 | E40: =D40+Forecast_IS!E45+Forecast_CF!E29 -> 6104.488 | F40: =E40+Forecast_IS!F45+Forecast_CF!F29 -> 6213.3004 | G40: =F40+Forecast_IS!G45+Forecast_CF!G29 -> 6318.9465 | H40: =G40+Forecast_IS!H45+Forecast_CF!H29 -> 6427.4503 | I40: =H40+Forecast_IS!I45+Forecast_CF!I29 -> 6538.394 | J40: =D40+Forecast_IS!J45+Forecast_CF!J29 -> 6123.0659 | K40: =J40+Forecast_IS!K45+Forecast_CF!K29 -> 6241.4272 | L40: =K40+Forecast_IS!L45+Forecast_CF!L29 -> 6359.9188 | M40: =L40+Forecast_IS!M45+Forecast_CF!M29 -> 6481.9428 | N40: =M40+Forecast_IS!N45+Forecast_CF!N29 -> 6606.9692 | O40: =D40+Forecast_IS!O45+Forecast_CF!O29 -> 6137.4253 | P40: =O40+Forecast_IS!P45+Forecast_CF!P29 -> 6269.153 | Q40: =P40+Forecast_IS!Q45+Forecast_CF!Q29 -> 6405.927 | R40: =Q40+Forecast_IS!R45+Forecast_CF!R29 -> 6541.3865 | S40: =R40+Forecast_IS!S45+Forecast_CF!S29 -> 6680.3522
A41: Total Equity | B41: ='Balance Sheet'!E42 -> 17430 | C41: ='Balance Sheet'!F42 -> 39862 | D41: ='Balance Sheet'!G42 -> 42967 | E41: =E39+E40 -> 43609.039 | F41: =F39+F40 -> 44717.879 | G41: =G39+G40 -> 45869.652 | H41: =H39+H40 -> 47339.544 | I41: =I39+I40 -> 48913.175 | J41: =J39+J40 -> 44684.566 | K41: =K39+K40 -> 46308.47 | L41: =L39+L40 -> 48146.178 | ... S41: =S39+S40 -> 56729.68
A42: TOTAL LIABILITIES & EQUITY | B42: ='Balance Sheet'!E43 -> 29001 | C42: ='Balance Sheet'!F43 -> 67292 | D42: ='Balance Sheet'!G43 -> 71059 | E42: =E32+E41 -> 70210.636 | F42: =F32+F41 -> 69827.979 | G42: =G32+G41 -> 69442.716 | H42: =H32+H41 -> 69468.982 | I42: =I32+I41 -> 69592.872 | J42: =J32+J41 -> 71587.122 | K42: =K32+K41 -> 71577.15 | L42: =L32+L41 -> 71933.996 | ... S42: =S32+S41 -> 77877.855
A44: CHECK: Total Assets − Total L&E (must = 0) | B44: ='Balance Sheet'!E19-'Balance Sheet'!E43 -> 0 | C44: ='Balance Sheet'!F19-'Balance Sheet'!F43 -> 0 | D44: ='Balance Sheet'!G19-'Balance Sheet'!G43 -> 0 | E44: =E18-E42 -> 13 | F44: =F18-F42 -> 13 | G44: =G18-G42 -> 13 | H44: =H18-H42 -> 13 | I44: =I18-I42 -> 13 | J44: =J18-J42 -> 13 | K44: =K18-K42 -> 13 | L44: =L18-L42 -> 13 | ... S44: =S18-S42 -> 13 | T44: reflect simplification in derivative instriments

Sheet Forecast_CF
A1: DIAMONDBACK ENERGY (FANG) — FORECAST CASH FLOW STATEMENT | $M
B2: HISTORICAL | E2: BEAR | J2: BASE | O2: BULL
B3: 2023A | C3: 2024A | D3: 2025A | E3: 2026E | F3: 2027E | G3: 2028E | H3: 2029E | I3: 2030E | J3: 2026E | K3: 2027E | L3: 2028E | M3: 2029E | N3: 2030E | O3: 2026E | P3: 2027E | Q3: 2028E | R3: 2029E | S3: 2030E
A4: CASH FROM OPERATIONS ($M)
A5: Net Income | B5: ='Cash Flow Statement'!E4 -> 3336 | C5: ='Cash Flow Statement'!F4 -> 3701 | D5: ='Cash Flow Statement'!G4 -> 1547 | E5: =Forecast_IS!E44 -> 5158.9488 | F5: =Forecast_IS!F44 -> 4923.2569 | G5: =Forecast_IS!G44 -> 4462.3988 | H5: =Forecast_IS!H44 -> 4678.6623 | I5: =Forecast_IS!I44 -> 4868.3725 | J5: =Forecast_IS!J44 -> 7104.2208 | K5: =Forecast_IS!K44 -> 5856.9282 | L5: =Forecast_IS!L44 -> 5706.2297 | ... S5: =Forecast_IS!S44 -> 7504.2985
A6: Add: Depreciation, Depletion & Amortization | B6: ='Cash Flow Statement'!E7 -> 1746 | C6: ='Cash Flow Statement'!F7 -> 2850 | D6: ='Cash Flow Statement'!G7 -> 5038 | E6: =Forecast_IS!E31 -> 5256.7568 | F6: =Forecast_IS!F31 -> 5434.0886 | G6: =Forecast_IS!G31 -> 5576.0058 | H6: =Forecast_IS!H31 -> 5693.8974 | I6: =Forecast_IS!I31 -> 5792.4649 | J6: =Forecast_IS!J31 -> 5293.981 | K6: =Forecast_IS!K31 -> 5511.3628 | L6: =Forecast_IS!L31 -> 5689.1652 | ... S6: =Forecast_IS!S31 -> 6120.4434
A7: Add: Deferred Income Taxes | B7: ='Cash Flow Statement'!E6 -> 378 | C7: ='Cash Flow Statement'!F6 -> 15 | D7: ='Cash Flow Statement'!G6 -> -519 | E7: =0 -> 0 | F7: =0 -> 0 | G7: =0 -> 0 | H7: =0 -> 0 | I7: =0 -> 0 | J7: =0 -> 0 | K7: =0 -> 0 | L7: =0 -> 0 | ... S7: =0 -> 0
A8: Other Non-Cash Items [held at 2023A] | B8: ='Cash Flow Statement'!E12 -> 11 | C8: ='Cash Flow Statement'!F12 -> 133 | D8: ='Cash Flow Statement'!G12 -> -430 | E8: 0 | F8: 0 | G8: 0 | H8: 0 | I8: 0 | J8: 0 | K8: 0 | L8: 0 | M8: 0 | N8: 0 | O8: 0 | P8: 0 | Q8: 0 | R8: 0 | S8: 0
